<dec f='include/python3.8/pyerrors.h' l='17' type='void PyErr_Fetch(PyObject ** , PyObject ** , PyObject ** )'/>
<use f='llvm/build/tools/lldb/bindings/python/LLDBWrapPython.cpp' l='917' u='c' c='_ZL23SWIG_Python_AddErrorMsgPKc'/>
<use f='llvm/build/tools/lldb/bindings/python/LLDBWrapPython.cpp' l='952' u='c' c='_ZL34SWIG_Python_RaiseOrModifyTypeErrorPKc'/>
<use f='llvm/build/tools/lldb/bindings/python/LLDBWrapPython.cpp' l='1547' u='c' c='_ZL20SwigPyObject_deallocP7_object'/>
<use f='llvm/build/tools/lldb/bindings/python/LLDBWrapPython.cpp' l='2480' u='c' c='_ZL22SWIG_Python_AddErrMesgPKci'/>
<use f='llvm/lldb/source/Plugins/ScriptInterpreter/Python/PythonDataObjects.cpp' l='1024' u='c' c='_ZN12lldb_private6python15PythonExceptionC1EPKc'/>
